Workbook

Sheet Inventory_Accuracy
A1: Date | B1: Shift | C1: SKU | D1: Bin_Location | E1: System_Count | F1: Physical_Count | G1: Abs_Variance | H1: Discrepancy_Rate_% | I1: Counter_Initials
A2: 45926 | B2: AM | C2: 235292 | D2: ZoneA-32 | E2: 14 | F2: 12 | G2: 2 | H2: 14.29 | I2: Faith
A3: 45930 | B3: AM | C3: 461432 | D3: ZoneA-38 | E3: 13 | F3: 14 | G3: 1 | H3: 7.69 | I3: Jake
A4: 45927 | B4: PM | C4: 145594 | D4: ZoneA-14 | E4: 16 | F4: 16 | G4: 0 | H4: 0 | I4: Brandon
A5: 45924 | B5: PM | C5: 443977 | D5: ZoneA-13 | E5: 6 | F5: 7 | G5: 1 | H5: 16.67 | I5: Brandon
A6: 45935 | B6: AM | C6: 989345 | D6: ZoneA-34 | E6: 5 | F6: 7 | G6: 2 | H6: 40 | I6: Jake
A7: 45933 | B7: AM | C7: 683418 | D7: ZoneA-48 | E7: 16 | F7: 17 | G7: 1 | H7: 6.25 | I7: Yash
A8: 45925 | B8: PM | C8: 505790 | D8: ZoneA-28 | E8: 9 | F8: 10 | G8: 1 | H8: 11.11 | I8: Yash
A9: 45933 | B9: AM | C9: 936952 | D9: ZoneA-8 | E9: 6 | F9: 4 | G9: 2 | H9: 33.33 | I9: Brandon
A10: 45927 | B10: AM | C10: 799115 | D10: ZoneA-48 | E10: 21 | F10: 21 | G10: 0 | H10: 0 | I10: Yash
A11: 45934 | B11: PM | C11: 527008 | D11: ZoneA-20 | E11: 14 | F11: 16 | G11: 2 | H11: 14.29 | I11: Yash
A12: 45927 | B12: PM | C12: 256598 | D12: ZoneA-49 | E12: 23 | F12: 23 | G12: 0 | H12: 0 | I12: Hunter
A13: 45935 | B13: AM | C13: 678394 | D13: ZoneA-20 | E13: 30 | F13: 29 | G13: 1 | H13: 3.33 | I13: Hunter
... A101: 45933 | B101: AM | C101: 100389 | D101: ZoneA-32 | E101: 23 | F101: 22 | G101: 1 | H101: 4.35 | I101: Faith

Sheet Reconciliation_Time
A1: Date | B1: SKU | C1: Discrepancy_ID | D1: Detected_Timestamp | E1: Resolved_Timestamp | F1: Reconciliation_Time_hours | G1: Owner | H1: Notes
A2: 45931 | B2: 232763 | C2: D001 | D2: 45931.33 | E2: 45931.492 | F2: 3.9 | G2: Hunter | H2: Pending
A3: 45925 | B3: 716625 | C3: D002 | D3: 45925.338 | E3: 45925.39 | F3: 1.25 | G3: Yash | H3: Pending
A4: 45925 | B4: 736011 | C4: D003 | D4: 45925.377 | E4: 45925.441 | F4: 1.53 | G4: Faith | H4: Checked
A5: 45935 | B5: 153652 | C5: D004 | D5: 45935.262 | E5: 45935.514 | F5: 6.05 | G5: Jake | H5: Resolved
A6: 45934 | B6: 844576 | C6: D005 | D6: 45934.419 | E6: 45934.695 | F6: 6.63 | G6: Jake | H6: Resolved
A7: 45933 | B7: 176753 | C7: D006 | D7: 45933.45 | E7: 45933.735 | F7: 6.83 | G7: Yash | H7: Resolved
A8: 45927 | B8: 647046 | C8: D007 | D8: 45927.459 | E8: 45927.504 | F8: 1.08 | G8: Faith | H8: Checked
A9: 45933 | B9: 884602 | C9: D008 | D9: 45933.416 | E9: 45933.515 | F9: 2.37 | G9: Yash | H9: Checked
A10: 45927 | B10: 575125 | C10: D009 | D10: 45927.418 | E10: 45927.529 | F10: 2.67 | G10: Brandon | H10: Pending
A11: 45930 | B11: 972765 | C11: D010 | D11: 45930.412 | E11: 45930.585 | F11: 4.13 | G11: Faith | H11: Checked
A12: 45931 | B12: 570066 | C12: D011 | D12: 45931.469 | E12: 45931.647 | F12: 4.27 | G12: Jake | H12: Pending
A13: 45929 | B13: 762768 | C13: D012 | D13: 45929.494 | E13: 45929.598 | F13: 2.5 | G13: Jake | H13: Checked
... A51: 45925 | B51: 687600 | C51: D050 | D51: 45925.374 | E51: 45925.455 | F51: 1.93 | G51: Hunter | H51: Checked

Sheet Picking_Time
A1: Date | B1: Shift | C1: Picker_ID | D1: Order_ID | E1: SKU | F1: Start_Timestamp | G1: End_Timestamp | H1: Picking_Time_min | I1: Exception_Flag | J1: Notes
A2: 45930 | B2: AM | C2: Brandon | D2: O2623 | E2: 526259 | F2: 45930.397 | G2: 45930.41 | H2: 19 | J2: On time
A3: 45935 | B3: AM | C3: Jake | D3: O8867 | E3: 685265 | F3: 45935.47 | G3: 45935.482 | H3: 17 | I3: Exception | J3: Damaged packaging
A4: 45926 | B4: PM | C4: Brandon | D4: O7626 | E4: 704687 | F4: 45926.357 | G4: 45926.363 | H4: 8 | J4: On time
A5: 45931 | B5: PM | C5: Hunter | D5: O6288 | E5: 550733 | F5: 45931.44 | G5: 45931.458 | H5: 25 | J5: Minor delay
A6: 45934 | B6: AM | C6: Faith | D6: O6466 | E6: 370335 | F6: 45934.398 | G6: 45934.412 | H6: 21 | J6: Minor delay
A7: 45935 | B7: AM | C7: Yash | D7: O8202 | E7: 251101 | F7: 45935.529 | G7: 45935.537 | H7: 11 | J7: On time
A8: 45933 | B8: PM | C8: Jake | D8: O2873 | E8: 784006 | F8: 45933.432 | G8: 45933.448 | H8: 23 | J8: Damaged packaging
A9: 45923 | B9: PM | C9: Yash | D9: O6904 | E9: 897700 | F9: 45923.557 | G9: 45923.563 | H9: 9 | J9: Minor delay
A10: 45927 | B10: PM | C10: Brandon | D10: O5014 | E10: 427900 | F10: 45927.562 | G10: 45927.574 | H10: 17 | J10: Minor delay
A11: 45933 | B11: PM | C11: Jake | D11: O5818 | E11: 559884 | F11: 45933.484 | G11: 45933.499 | H11: 22 | J11: Damaged packaging
A12: 45927 | B12: AM | C12: Brandon | D12: O9533 | E12: 454209 | F12: 45927.408 | G12: 45927.42 | H12: 17 | J12: Damaged packaging
A13: 45930 | B13: PM | C13: Brandon | D13: O7073 | E13: 124213 | F13: 45930.466 | G13: 45930.479 | H13: 19 | J13: On time
A14: 45927 | B14: PM | C14: Yash | D14: O3959 | E14: 452053 | F14: 45927.55 | G14: 45927.564 | H14: 20 | I14: Exception | J14: Minor delay
A15: 45927 | B15: AM | C15: Brandon | D15: O1739 | E15: 599987 | F15: 45927.366 | G15: 45927.374 | H15: 11 | J15: Damaged packaging
A16: 45925 | B16: PM | C16: Brandon | D16: O7574 | E16: 461685 | F16: 45925.449 | G16: 45925.46 | H16: 15 | I16: Exception | J16: Minor delay
A17: 45926 | B17: PM | C17: Brandon | D17: O6764 | E17: 777263 | F17: 45926.365 | G17: 45926.378 | H17: 19 | J17: Minor delay
A18: 45934 | B18: PM | C18: Yash | D18: O2550 | E18: 145303 | F18: 45934.387 | G18: 45934.393 | H18: 9 | J18: Damaged packaging
A19: 45935 | B19: AM | C19: Jake | D19: O2721 | E19: 506500 | F19: 45935.351 | G19: 45935.367 | H19: 23 | I19: Exception | J19: Damaged packaging
A20: 45930 | B20: PM | C20: Hunter | D20: O7780 | E20: 990646 | F20: 45930.338 | G20: 45930.347 | H20: 14 | J20: On time
A21: 45932 | B21: PM | C21: Hunter | D21: O3647 | E21: 274831 | F21: 45932.397 | G21: 45932.413 | H21: 23 | J21: Damaged packaging
A22: 45930 | B22: PM | C22: Jake | D22: O8522 | E22: 596068 | F22: 45930.557 | G22: 45930.566 | H22: 13 | J22: Damaged packaging
A23: 45929 | B23: AM | C23: Faith | D23: O8923 | E23: 639165 | F23: 45929.573 | G23: 45929.58 | H23: 10 | I23: Exception | J23: On time
A24: 45930 | B24: PM | C24: Jake | D24: O9004 | E24: 445021 | F24: 45930.38 | G24: 45930.39 | H24: 14 | I24: Exception | J24: Minor delay
A25: 45930 | B25: AM | C25: Jake | D25: O9251 | E25: 868832 | F25: 45930.544 | G25: 45930.551 | H25: 10 | I25: Exception | J25: Minor delay
A26: 45935 | B26: AM | C26: Jake | D26: O8268 | E26: 234946 | F26: 45935.348 | G26: 45935.364 | H26: 23 | J26: Damaged packaging
A27: 45922 | B27: PM | C27: Brandon | D27: O5988 | E27: 680324 | F27: 45922.464 | G27: 45922.476 | H27: 18 | J27: Minor delay
A28: 45934 | B28: PM | C28: Yash | D28: O6485 | E28: 557171 | F28: 45934.572 | G28: 45934.589 | H28: 24 | I28: Exception | J28: On time
A29: 45926 | B29: PM | C29: Faith | D29: O4101 | E29: 353705 | F29: 45926.458 | G29: 45926.47 | H29: 17 | J29: Minor delay
A30: 45932 | B30: PM | C30: Hunter | D30: O4939 | E30: 314156 | F30: 45932.418 | G30: 45932.429 | H30: 16 | J30: Minor delay
A31: 45927 | B31: AM | C31: Faith | D31: O1008 | E31: 592977 | F31: 45927.424 | G31: 45927.435 | H31: 15 | J31: On time

Sheet Root_Cause_Log
A1: Date | B1: SKU | C1: Discrepancy_ID | D1: Cause_Category | E1: Detail_Notes | F1: Corrective_Action | G1: Verification_Date
A2: 45924 | B2: 511244 | C2: RC001 | D2: System Lag | E2: Counting error by temp staff | F2: Reprinted barcode label | G2: 45925
A3: 45923 | B3: 732880 | C3: RC002 | D3: Misplaced | E3: Mis-scan - label damaged | F3: Added double-check process | G3: 45924
A4: 45931 | B4: 397523 | C4: RC003 | D4: Mis-scan | E4: Found misplaced in Zone B | F4: Retrained staff | G4: 45934
A5: 45922 | B5: 303227 | C5: RC004 | D5: Mis-scan | E5: Wrong UoM setup | F5: Retrained staff | G5: 45924
A6: 45923 | B6: 494598 | C6: RC005 | D6: System Lag | E6: Counting error by temp staff | F6: Added double-check process | G6: 45926
A7: 45927 | B7: 899662 | C7: RC006 | D7: Wrong UoM | E7: Mis-scan - label damaged | F7: Updated SOP | G7: 45929
A8: 45922 | B8: 142421 | C8: RC007 | D8: Counting Error | E8: Mis-scan - label damaged | F8: Retrained staff | G8: 45923
A9: 45926 | B9: 424923 | C9: RC008 | D9: Wrong UoM | E9: Counting error by temp staff | F9: Retrained staff | G9: 45927
A10: 45923 | B10: 253231 | C10: RC009 | D10: Damaged/Return | E10: Wrong UoM setup | F10: Retrained staff | G10: 45924
A11: 45932 | B11: 812637 | C11: RC010 | D11: Wrong UoM | E11: Counting error by temp staff | F11: Updated SOP | G11: 45933
A12: 45927 | B12: 563741 | C12: RC011 | D12: Damaged/Return | E12: Mis-scan - label damaged | F12: Added double-check process | G12: 45930
A13: 45933 | B13: 826869 | C13: RC012 | D13: Damaged/Return | E13: Wrong UoM setup | F13: Reprinted barcode label | G13: 45936
... A21: 45929 | B21: 734390 | C21: RC020 | D21: Misplaced | E21: Found misplaced in Zone B | F21: Reprinted barcode label | G21: 45932

Sheet KPIs
A1: Metric | B1: Value (Linked)
A2: Inventory Accuracy % (overall) | B2: =100-AVERAGE(Inventory_Accuracy!$H$2:$H$101) -> 89.9088
A3: Avg Discrepancy Rate % | B3: =AVERAGE(Inventory_Accuracy!$H$2:$H$101) -> 10.0912
A4: Avg Reconciliation Time (hrs) | B4: =AVERAGE(Reconciliation_Time!$F$2:$F$51) -> 4.3546
A5: Avg Picking Time (min) | B5: =AVERAGE(Picking_Time!$H$2:$H$31) -> 16.733333
A6: Total Root Cause Records | B6: =ROWS(Root_Cause_Log!$A$2:$A$21) -> 20

Sheet Daily_Metrics
A1: Date | B1: Avg Discrepancy Rate | C1: Mean | D1: UCL (+3σ) | E1: LCL (-3σ) | G1: Date | H1: Avg Recon Hours | K1: Date | L1: Avg Pick Min
A2: 45922 | B2: =AVERAGEIF(Inventory_Accuracy!$A$2:$A$101,A2,Inventory_Accuracy!$H$2:$H$101) -> 9.9325 | C2: =AVERAGE(B2:B15) -> 10.125027 | D2: =C2+3*Sigma_Calc!B3 -> 21.914511 | E2: 0 | G2: 45922 | H2: =AVERAGEIF(Reconciliation_Time!$A$2:$A$51,G2,Reconciliation_Time!$F$2:$F$51) -> 4.9366667 | K2: 45922 | L2: =AVERAGEIF(Picking_Time!$A$2:$A$31,K2,Picking_Time!$H$2:$H$31) -> 18
A3: 45923 | B3: =AVERAGEIF(Inventory_Accuracy!$A$2:$A$101,A3,Inventory_Accuracy!$H$2:$H$101) -> 2.78 | C3: =$C$2 -> 10.125027 | D3: =$D$2 -> 21.914511 | E3: 0 | G3: 45923 | H3: =AVERAGEIF(Reconciliation_Time!$A$2:$A$51,G3,Reconciliation_Time!$F$2:$F$51) -> 5.382 | K3: 45923 | L3: =AVERAGEIF(Picking_Time!$A$2:$A$31,K3,Picking_Time!$H$2:$H$31) -> 9
A4: 45924 | B4: =AVERAGEIF(Inventory_Accuracy!$A$2:$A$101,A4,Inventory_Accuracy!$H$2:$H$101) -> 10.846667 | C4: =$C$2 -> 10.125027 | D4: =$D$2 -> 21.914511 | E4: 0 | G4: 45924 | H4: =AVERAGEIF(Reconciliation_Time!$A$2:$A$51,G4,Reconciliation_Time!$F$2:$F$51) -> 4.065 | K4: 45925 | L4: =AVERAGEIF(Picking_Time!$A$2:$A$31,K4,Picking_Time!$H$2:$H$31) -> 15
A5: 45925 | B5: =AVERAGEIF(Inventory_Accuracy!$A$2:$A$101,A5,Inventory_Accuracy!$H$2:$H$101) -> 8.47 | C5: =$C$2 -> 10.125027 | D5: =$D$2 -> 21.914511 | E5: 0 | G5: 45925 | H5: =AVERAGEIF(Reconciliation_Time!$A$2:$A$51,G5,Reconciliation_Time!$F$2:$F$51) -> 3.6866667 | K5: 45926 | L5: =AVERAGEIF(Picking_Time!$A$2:$A$31,K5,Picking_Time!$H$2:$H$31) -> 14.666667
A6: 45926 | B6: =AVERAGEIF(Inventory_Accuracy!$A$2:$A$101,A6,Inventory_Accuracy!$H$2:$H$101) -> 18.275714 | C6: =$C$2 -> 10.125027 | D6: =$D$2 -> 21.914511 | E6: 0 | G6: 45926 | H6: =AVERAGEIF(Reconciliation_Time!$A$2:$A$51,G6,Reconciliation_Time!$F$2:$F$51) -> 6.4 | K6: 45927 | L6: =AVERAGEIF(Picking_Time!$A$2:$A$31,K6,Picking_Time!$H$2:$H$31) -> 16
A7: 45927 | B7: =AVERAGEIF(Inventory_Accuracy!$A$2:$A$101,A7,Inventory_Accuracy!$H$2:$H$101) -> 8.4578571 | C7: =$C$2 -> 10.125027 | D7: =$D$2 -> 21.914511 | E7: 0 | G7: 45927 | H7: =AVERAGEIF(Reconciliation_Time!$A$2:$A$51,G7,Reconciliation_Time!$F$2:$F$51) -> 2.776 | K7: 45929 | L7: =AVERAGEIF(Picking_Time!$A$2:$A$31,K7,Picking_Time!$H$2:$H$31) -> 10
A8: 45928 | B8: =AVERAGEIF(Inventory_Accuracy!$A$2:$A$101,A8,Inventory_Accuracy!$H$2:$H$101) -> 8.2966667 | C8: =$C$2 -> 10.125027 | D8: =$D$2 -> 21.914511 | E8: 0 | G8: 45928 | H8: =AVERAGEIF(Reconciliation_Time!$A$2:$A$51,G8,Reconciliation_Time!$F$2:$F$51) -> 5.0866667 | K8: 45930 | L8: =AVERAGEIF(Picking_Time!$A$2:$A$31,K8,Picking_Time!$H$2:$H$31) -> 14.833333
A9: 45929 | B9: =AVERAGEIF(Inventory_Accuracy!$A$2:$A$101,A9,Inventory_Accuracy!$H$2:$H$101) -> 6.2555556 | C9: =$C$2 -> 10.125027 | D9: =$D$2 -> 21.914511 | E9: 0 | G9: 45929 | H9: =AVERAGEIF(Reconciliation_Time!$A$2:$A$51,G9,Reconciliation_Time!$F$2:$F$51) -> 4.27 | K9: 45931 | L9: =AVERAGEIF(Picking_Time!$A$2:$A$31,K9,Picking_Time!$H$2:$H$31) -> 25
A10: 45930 | B10: =AVERAGEIF(Inventory_Accuracy!$A$2:$A$101,A10,Inventory_Accuracy!$H$2:$H$101) -> 11.80875 | C10: =$C$2 -> 10.125027 | D10: =$D$2 -> 21.914511 | E10: 0 | G10: 45930 | H10: =AVERAGEIF(Reconciliation_Time!$A$2:$A$51,G10,Reconciliation_Time!$F$2:$F$51) -> 4.5266667 | K10: 45932 | L10: =AVERAGEIF(Picking_Time!$A$2:$A$31,K10,Picking_Time!$H$2:$H$31) -> 19.5
A11: 45931 | B11: =AVERAGEIF(Inventory_Accuracy!$A$2:$A$101,A11,Inventory_Accuracy!$H$2:$H$101) -> 11.501667 | C11: =$C$2 -> 10.125027 | D11: =$D$2 -> 21.914511 | E11: 0 | G11: 45931 | H11: =AVERAGEIF(Reconciliation_Time!$A$2:$A$51,G11,Reconciliation_Time!$F$2:$F$51) -> 3.4325 | K11: 45933 | L11: =AVERAGEIF(Picking_Time!$A$2:$A$31,K11,Picking_Time!$H$2:$H$31) -> 22.5
A12: 45932 | B12: =AVERAGEIF(Inventory_Accuracy!$A$2:$A$101,A12,Inventory_Accuracy!$H$2:$H$101) -> 7.7483333 | C12: =$C$2 -> 10.125027 | D12: =$D$2 -> 21.914511 | E12: 0 | G12: 45932 | H12: =AVERAGEIF(Reconciliation_Time!$A$2:$A$51,G12,Reconciliation_Time!$F$2:$F$51) -> 2.42 | K12: 45934 | L12: =AVERAGEIF(Picking_Time!$A$2:$A$31,K12,Picking_Time!$H$2:$H$31) -> 18
A13: 45933 | B13: =AVERAGEIF(Inventory_Accuracy!$A$2:$A$101,A13,Inventory_Accuracy!$H$2:$H$101) -> 8.3125 | C13: =$C$2 -> 10.125027 | D13: =$D$2 -> 21.914511 | E13: 0 | G13: 45933 | H13: =AVERAGEIF(Reconciliation_Time!$A$2:$A$51,G13,Reconciliation_Time!$F$2:$F$51) -> 4.285 | K13: 45935 | L13: =AVERAGEIF(Picking_Time!$A$2:$A$31,K13,Picking_Time!$H$2:$H$31) -> 18.5
A14: 45934 | B14: =AVERAGEIF(Inventory_Accuracy!$A$2:$A$101,A14,Inventory_Accuracy!$H$2:$H$101) -> 15.851667 | C14: =$C$2 -> 10.125027 | D14: =$D$2 -> 21.914511 | E14: 0 | G14: 45934 | H14: =AVERAGEIF(Reconciliation_Time!$A$2:$A$51,G14,Reconciliation_Time!$F$2:$F$51) -> 4.5333333
A15: 45935 | B15: =AVERAGEIF(Inventory_Accuracy!$A$2:$A$101,A15,Inventory_Accuracy!$H$2:$H$101) -> 13.2125 | C15: =$C$2 -> 10.125027 | D15: =$D$2 -> 21.914511 | E15: 0 | G15: 45935 | H15: =AVERAGEIF(Reconciliation_Time!$A$2:$A$51,G15,Reconciliation_Time!$F$2:$F$51) -> 5.254

Sheet Sigma_Calc
A1: Sigma & Control Limit Calculations (Linked to Daily_Metrics)
A2: Mean (μ) | B2: =AVERAGE(Daily_Metrics!B2:B15) -> 10.125027
A3: Std Dev (σ) | B3: =_xlfn.STDEV.S(Daily_Metrics!B2:B15) -> 3.9298279
A4: UCL (μ + 3σ) | B4: =B2+3*B3 -> 21.914511
A5: LCL (μ - 3σ) | B5: =MAX(B2-3*B3,0) -> 0
A7: Target Discrepancy Rate % (USL) | B7: 2
A8: Sigma Level (Z) vs USL | B8: =(B7-B2)/B3 -> -2.0675274
A9: Estimated DPMO (one-sided vs USL) | B9: =(1-_xlfn.NORM.S.DIST(B8,TRUE))*1000000 -> 980657.76

Sheet Technician_Comparison
A1: Counter_Initials | B1: Avg Discrepancy Rate %
A2: Brandon | B2: =AVERAGEIF(Inventory_Accuracy!$I$2:$I$101,A2,Inventory_Accuracy!$H$2:$H$101) -> 12.408571
A3: Faith | B3: =AVERAGEIF(Inventory_Accuracy!$I$2:$I$101,A3,Inventory_Accuracy!$H$2:$H$101) -> 8.004
A4: Hunter | B4: =AVERAGEIF(Inventory_Accuracy!$I$2:$I$101,A4,Inventory_Accuracy!$H$2:$H$101) -> 11.880417
A5: Jake | B5: =AVERAGEIF(Inventory_Accuracy!$I$2:$I$101,A5,Inventory_Accuracy!$H$2:$H$101) -> 11.12
A6: Yash | B6: =AVERAGEIF(Inventory_Accuracy!$I$2:$I$101,A6,Inventory_Accuracy!$H$2:$H$101) -> 7.215

Sheet Pareto_Causes
A1: Cause_Category | B1: Count | C1: Cum_Count | D1: Cum_Pct
A2: Counting Error | B2: =COUNTIF(Root_Cause_Log!$D$2:$D$21,A2) -> 2 | C2: =B2 -> 2 | D2: =C2/SUM(B2:B7)*100 -> 10
A3: Damaged/Return | B3: =COUNTIF(Root_Cause_Log!$D$2:$D$21,A3) -> 3 | C3: =C2+B3 -> 5 | D3: =C3/SUM(B2:B7)*100 -> 25
A4: Mis-scan | B4: =COUNTIF(Root_Cause_Log!$D$2:$D$21,A4) -> 5 | C4: =C3+B4 -> 10 | D4: =C4/SUM(B2:B7)*100 -> 50
A5: Misplaced | B5: =COUNTIF(Root_Cause_Log!$D$2:$D$21,A5) -> 3 | C5: =C4+B5 -> 13 | D5: =C5/SUM(B2:B7)*100 -> 65
A6: System Lag | B6: =COUNTIF(Root_Cause_Log!$D$2:$D$21,A6) -> 4 | C6: =C5+B6 -> 17 | D6: =C6/SUM(B2:B7)*100 -> 85
A7: Wrong UoM | B7: =COUNTIF(Root_Cause_Log!$D$2:$D$21,A7) -> 3 | C7: =C6+B7 -> 20 | D7: =C7/SUM(B2:B7)*100 -> 100

Sheet Charts

Sheet Hypothesis_Tests
A1: Cutover_Date (After = Date > Cutover) | B1: {=INDEX(Daily_Metrics!$A$2:$A$15,ROUNDUP(COUNTA(Daily_Metrics!$A$2:$A$15)/2,0))} -> 45928
A2: Edit B1 to your actual process change date. All tests below update automatically.
A4: Inventory Discrepancy Rate (%) - Before/After Split
A5: Date | B5: Avg_Discrep_Rate | C5: Group (Before/After) | F5: Before_Rates | G5: After_Rates
A6: =Daily_Metrics!A2 -> 45922 | B6: =Daily_Metrics!B2 -> 9.9325 | C6: =IF(A6>$B$1,"After","Before") -> Before | F6: {=_xlfn._xlws.FILTER(B6:B19,C6:C19="Before")} -> 9.9325 | G6: {=_xlfn._xlws.FILTER(B6:B19,C6:C19="After")} -> 0
A7: One-tailed t-test (H1: After < Before) | B7: 0 | C7: =IF(A7>$B$1,"After","Before") -> After | F7: 10.846667 | G7: 6.2555556
A8: =Daily_Metrics!A4 -> 45924 | B8: =Daily_Metrics!B4 -> 10.846667 | C8: =IF(A8>$B$1,"After","Before") -> Before | F8: 8.47 | G8: 11.80875
A9: =Daily_Metrics!A5 -> 45925 | B9: =Daily_Metrics!B5 -> 8.47 | C9: =IF(A9>$B$1,"After","Before") -> Before | F9: 18.275714 | G9: 11.501667
A10: =Daily_Metrics!A6 -> 45926 | B10: =Daily_Metrics!B6 -> 18.275714 | C10: =IF(A10>$B$1,"After","Before") -> Before | F10: 8.4578571 | G10: 7.7483333
A11: =Daily_Metrics!A7 -> 45927 | B11: =Daily_Metrics!B7 -> 8.4578571 | C11: =IF(A11>$B$1,"After","Before") -> Before | F11: 8.2966667 | G11: 8.3125
A12: =Daily_Metrics!A8 -> 45928 | B12: =Daily_Metrics!B8 -> 8.2966667 | C12: =IF(A12>$B$1,"After","Before") -> Before | G12: 15.851667
A13: =Daily_Metrics!A9 -> 45929 | B13: =Daily_Metrics!B9 -> 6.2555556 | C13: =IF(A13>$B$1,"After","Before") -> After | G13: 13.2125
A14: =Daily_Metrics!A10 -> 45930 | B14: =Daily_Metrics!B10 -> 11.80875 | C14: =IF(A14>$B$1,"After","Before") -> After
A15: =Daily_Metrics!A11 -> 45931 | B15: =Daily_Metrics!B11 -> 11.501667 | C15: =IF(A15>$B$1,"After","Before") -> After
A16: =Daily_Metrics!A12 -> 45932 | B16: =Daily_Metrics!B12 -> 7.7483333 | C16: =IF(A16>$B$1,"After","Before") -> After
A17: =Daily_Metrics!A13 -> 45933 | B17: =Daily_Metrics!B13 -> 8.3125 | C17: =IF(A17>$B$1,"After","Before") -> After
A18: =Daily_Metrics!A14 -> 45934 | B18: =Daily_Metrics!B14 -> 15.851667 | C18: =IF(A18>$B$1,"After","Before") -> After
A19: =Daily_Metrics!A15 -> 45935 | B19: =Daily_Metrics!B15 -> 13.2125 | C19: =IF(A19>$B$1,"After","Before") -> After
A22: Reconciliation Time (hrs) - Before/After Split
A23: Date | B23: Avg_Recon_Hours | C23: Group | F23: Before_Hours | G23: After_Hours
A24: =Daily_Metrics!G2 -> 45922 | B24: =Daily_Metrics!H2 -> 4.9366667 | C24: =IF(A24>$B$1,"After","Before") -> Before | F24: {=_xlfn._xlws.FILTER(B23:B37,C23:C37="Before")} -> 4.9366667 | G24: {=_xlfn._xlws.FILTER(B23:B37,C23:C37="After")} -> 0
A25: One-tailed t-test (H1: After < Before) | B25: 0 | C25: =IF(A25>$B$1,"After","Before") -> After | F25: 4.065 | G25: 4.27
A26: =Daily_Metrics!G4 -> 45924 | B26: =Daily_Metrics!H4 -> 4.065 | C26: =IF(A26>$B$1,"After","Before") -> Before | F26: 3.6866667 | G26: 4.5266667
A27: =Daily_Metrics!G5 -> 45925 | B27: =Daily_Metrics!H5 -> 3.6866667 | C27: =IF(A27>$B$1,"After","Before") -> Before | F27: 6.4 | G27: 3.4325
A28: =Daily_Metrics!G6 -> 45926 | B28: =Daily_Metrics!H6 -> 6.4 | C28: =IF(A28>$B$1,"After","Before") -> Before | F28: 2.776 | G28: 2.42
A29: =Daily_Metrics!G7 -> 45927 | B29: =Daily_Metrics!H7 -> 2.776 | C29: =IF(A29>$B$1,"After","Before") -> Before | F29: 5.0866667 | G29: 4.285
A30: =Daily_Metrics!G8 -> 45928 | B30: =Daily_Metrics!H8 -> 5.0866667 | C30: =IF(A30>$B$1,"After","Before") -> Before | G30: 4.5333333
A31: =Daily_Metrics!G9 -> 45929 | B31: =Daily_Metrics!H9 -> 4.27 | C31: =IF(A31>$B$1,"After","Before") -> After | G31: 5.254
A32: =Daily_Metrics!G10 -> 45930 | B32: =Daily_Metrics!H10 -> 4.5266667 | C32: =IF(A32>$B$1,"After","Before") -> After
A33: =Daily_Metrics!G11 -> 45931 | B33: =Daily_Metrics!H11 -> 3.4325 | C33: =IF(A33>$B$1,"After","Before") -> After
A34: =Daily_Metrics!G12 -> 45932 | B34: =Daily_Metrics!H12 -> 2.42 | C34: =IF(A34>$B$1,"After","Before") -> After
A35: =Daily_Metrics!G13 -> 45933 | B35: =Daily_Metrics!H13 -> 4.285 | C35: =IF(A35>$B$1,"After","Before") -> After
A36: =Daily_Metrics!G14 -> 45934 | B36: =Daily_Metrics!H14 -> 4.5333333 | C36: =IF(A36>$B$1,"After","Before") -> After
A37: =Daily_Metrics!G15 -> 45935 | B37: =Daily_Metrics!H15 -> 5.254 | C37: =IF(A37>$B$1,"After","Before") -> After
A40: Picking Time (min) - Before/After Split
A41: Date | B41: Avg_Pick_Min | C41: Group | F41: Before_Min | G41: After_Min
A42: =Daily_Metrics!K2 -> 45922 | B42: =Daily_Metrics!L2 -> 18 | C42: =IF(A42>$B$1,"After","Before") -> Before | F42: {=_xlfn._xlws.FILTER(B41:B53,C41:C53="Before")} -> 18 | G42: {=_xlfn._xlws.FILTER(B41:B53,C41:C53="After")} -> 0
A43: One-tailed t-test (H1: After < Before) | B43: 0 | C43: =IF(A43>$B$1,"After","Before") -> After | F43: 15 | G43: 10
A44: =Daily_Metrics!K4 -> 45925 | B44: =Daily_Metrics!L4 -> 15 | C44: =IF(A44>$B$1,"After","Before") -> Before | F44: 14.666667 | G44: 14.833333
A45: =Daily_Metrics!K5 -> 45926 | B45: =Daily_Metrics!L5 -> 14.666667 | C45: =IF(A45>$B$1,"After","Before") -> Before | F45: 16 | G45: 25
...
